Workbook

Sheet base
A1: Date/Time | B1: Faixa | C1: Store Code | D1: Store Name | E1: Device Code | F1: Device Name | G1: Sessions | H1: Aparelho | I1: Tipo | J1: Rede | K1: 80/20 | L1: Shopping | M1: Visibilidade | N1: Regional
A2: 46113.417 | B2: =MOD(Table_Sheet1[[#This Row],[Date/Time]],1) -> 0.41666667 | C2: SPC11232 | D2: CASAS BAHIA - PRACA FLORIANO PEIXOTO, 38 - ZONA COMERCIAL - SPC11232 | E2: Edge60Fusion256_SPC11232 | F2: Edge60Fusion256_SPC11232 | G2: 2 | H2: =VLOOKUP(Table_Sheet1[[#This Row],[Device Name]],'[1]AParelhos_&_LOJAS'!$C:$H,6,0) -> Edge 60 Fusion | I2: =VLOOKUP(Table_Sheet1[[#This Row],[Device Name]],'[1]AParelhos_&_LOJAS'!$C:$I,7,0) -> 256 GB | J2: =VLOOKUP(Table_Sheet1[[#This Row],[Store Name]],'lojas comp prom'!B:T,19,0) -> CASAS BAHIA | K2: =VLOOKUP(Table_Sheet1[[#This Row],[Store Name]],'lojas comp prom'!B:Z,25,0) -> 80 | L2: =VLOOKUP(Table_Sheet1[[#This Row],[Store Name]],'lojas comp prom'!B:S,18,0) -> Loja De Rua | M2: =VLOOKUP(Table_Sheet1[[#This Row],[Store Name]],'lojas comp prom'!B:AA,26,0) -> 0 | N2: =VLOOKUP(Table_Sheet1[[#This Row],[Store Name]],'lojas comp prom'!B:L,11,0) -> SPC
A3: 46113.417 | B3: =MOD(Table_Sheet1[[#This Row],[Date/Time]],1) -> 0.41666667 | C3: SPC11232 | D3: CASAS BAHIA - PRACA FLORIANO PEIXOTO, 38 - ZONA COMERCIAL - SPC11232 | E3: G05256_SPC11232 | F3: G05256_SPC11232 | G3: 2 | H3: =VLOOKUP(Table_Sheet1[[#This Row],[Device Name]],'[1]AParelhos_&_LOJAS'!$C:$H,6,0) -> G05 | I3: =VLOOKUP(Table_Sheet1[[#This Row],[Device Name]],'[1]AParelhos_&_LOJAS'!$C:$I,7,0) -> 256 GB | J3: =VLOOKUP(Table_Sheet1[[#This Row],[Store Name]],'lojas comp prom'!B:T,19,0) -> CASAS BAHIA | K3: =VLOOKUP(Table_Sheet1[[#This Row],[Store Name]],'lojas comp prom'!B:Z,25,0) -> 80 | L3: =VLOOKUP(Table_Sheet1[[#This Row],[Store Name]],'lojas comp prom'!B:S,18,0) -> Loja De Rua | M3: =VLOOKUP(Table_Sheet1[[#This Row],[Store Name]],'lojas comp prom'!B:AA,26,0) -> 0 | N3: =VLOOKUP(Table_Sheet1[[#This Row],[Store Name]],'lojas comp prom'!B:L,11,0) -> SPC
A4: 46113.417 | B4: =MOD(Table_Sheet1[[#This Row],[Date/Time]],1) -> 0.41666667 | C4: SPC11232 | D4: CASAS BAHIA - PRACA FLORIANO PEIXOTO, 38 - ZONA COMERCIAL - SPC11232 | E4: G06128_SPC11232 | F4: G06128_SPC11232 | G4: 2 | H4: =VLOOKUP(Table_Sheet1[[#This Row],[Device Name]],'[1]AParelhos_&_LOJAS'!$C:$H,6,0) -> G06 | I4: =VLOOKUP(Table_Sheet1[[#This Row],[Device Name]],'[1]AParelhos_&_LOJAS'!$C:$I,7,0) -> 128 GB | J4: =VLOOKUP(Table_Sheet1[[#This Row],[Store Name]],'lojas comp prom'!B:T,19,0) -> CASAS BAHIA | K4: =VLOOKUP(Table_Sheet1[[#This Row],[Store Name]],'lojas comp prom'!B:Z,25,0) -> 80 | L4: =VLOOKUP(Table_Sheet1[[#This Row],[Store Name]],'lojas comp prom'!B:S,18,0) -> Loja De Rua | M4: =VLOOKUP(Table_Sheet1[[#This Row],[Store Name]],'lojas comp prom'!B:AA,26,0) -> 0 | N4: =VLOOKUP(Table_Sheet1[[#This Row],[Store Name]],'lojas comp prom'!B:L,11,0) -> SPC
A5: 46113.417 | B5: =MOD(Table_Sheet1[[#This Row],[Date/Time]],1) -> 0.41666667 | C5: SPC11232 | D5: CASAS BAHIA - PRACA FLORIANO PEIXOTO, 38 - ZONA COMERCIAL - SPC11232 | E5: G06256_SPC11232 | F5: G06256_SPC11232 | G5: 1 | H5: =VLOOKUP(Table_Sheet1[[#This Row],[Device Name]],'[1]AParelhos_&_LOJAS'!$C:$H,6,0) -> G06 | I5: =VLOOKUP(Table_Sheet1[[#This Row],[Device Name]],'[1]AParelhos_&_LOJAS'!$C:$I,7,0) -> 256 GB | J5: =VLOOKUP(Table_Sheet1[[#This Row],[Store Name]],'lojas comp prom'!B:T,19,0) -> CASAS BAHIA | K5: =VLOOKUP(Table_Sheet1[[#This Row],[Store Name]],'lojas comp prom'!B:Z,25,0) -> 80 | L5: =VLOOKUP(Table_Sheet1[[#This Row],[Store Name]],'lojas comp prom'!B:S,18,0) -> Loja De Rua | M5: =VLOOKUP(Table_Sheet1[[#This Row],[Store Name]],'lojas comp prom'!B:AA,26,0) -> 0 | N5: =VLOOKUP(Table_Sheet1[[#This Row],[Store Name]],'lojas comp prom'!B:L,11,0) -> SPC
A6: 46113.417 | B6: =MOD(Table_Sheet1[[#This Row],[Date/Time]],1) -> 0.41666667 | C6: SPC11232 | D6: CASAS BAHIA - PRACA FLORIANO PEIXOTO, 38 - ZONA COMERCIAL - SPC11232 | E6: G17256_SPC11232 | F6: G17256_SPC11232 | G6: 2 | H6: =VLOOKUP(Table_Sheet1[[#This Row],[Device Name]],'[1]AParelhos_&_LOJAS'!$C:$H,6,0) -> G17 | I6: =VLOOKUP(Table_Sheet1[[#This Row],[Device Name]],'[1]AParelhos_&_LOJAS'!$C:$I,7,0) -> 256 GB | J6: =VLOOKUP(Table_Sheet1[[#This Row],[Store Name]],'lojas comp prom'!B:T,19,0) -> CASAS BAHIA | K6: =VLOOKUP(Table_Sheet1[[#This Row],[Store Name]],'lojas comp prom'!B:Z,25,0) -> 80 | L6: =VLOOKUP(Table_Sheet1[[#This Row],[Store Name]],'lojas comp prom'!B:S,18,0) -> Loja De Rua | M6: =VLOOKUP(Table_Sheet1[[#This Row],[Store Name]],'lojas comp prom'!B:AA,26,0) -> 0 | N6: =VLOOKUP(Table_Sheet1[[#This Row],[Store Name]],'lojas comp prom'!B:L,11,0) -> SPC
A7: 46113.417 | B7: =MOD(Table_Sheet1[[#This Row],[Date/Time]],1) -> 0.41666667 | C7: SPC287350 | D7: CASAS BAHIA - AVENIDA NACOES UNIDAS, 12995 - SPC287350 | E7: G56256_SPC287350 | F7: G56256_SPC287350 | G7: 1 | H7: =VLOOKUP(Table_Sheet1[[#This Row],[Device Name]],'[1]AParelhos_&_LOJAS'!$C:$H,6,0) -> G56 | I7: =VLOOKUP(Table_Sheet1[[#This Row],[Device Name]],'[1]AParelhos_&_LOJAS'!$C:$I,7,0) -> 256 GB | J7: =VLOOKUP(Table_Sheet1[[#This Row],[Store Name]],'lojas comp prom'!B:T,19,0) -> CASAS BAHIA | K7: =VLOOKUP(Table_Sheet1[[#This Row],[Store Name]],'lojas comp prom'!B:Z,25,0) -> 80 | L7: =VLOOKUP(Table_Sheet1[[#This Row],[Store Name]],'lojas comp prom'!B:S,18,0) -> Loja De Rua | M7: =VLOOKUP(Table_Sheet1[[#This Row],[Store Name]],'lojas comp prom'!B:AA,26,0) -> 0 | N7: =VLOOKUP(Table_Sheet1[[#This Row],[Store Name]],'lojas comp prom'!B:L,11,0) -> SPC
A8: 46113.417 | B8: =MOD(Table_Sheet1[[#This Row],[Date/Time]],1) -> 0.41666667 | C8: SPC7612 | D8: PONTO FRIO - AVENIDA INTERLAGOS, 2255 - SHOPPING INTERLAGOS - SPC7612 | E8: Edge50Fusion256_SPC7612 | F8: Edge50Fusion256_SPC7612 | G8: 1 | H8: =VLOOKUP(Table_Sheet1[[#This Row],[Device Name]],'[1]AParelhos_&_LOJAS'!$C:$H,6,0) -> Edge 50 Fusion | I8: =VLOOKUP(Table_Sheet1[[#This Row],[Device Name]],'[1]AParelhos_&_LOJAS'!$C:$I,7,0) -> 256 GB | J8: =VLOOKUP(Table_Sheet1[[#This Row],[Store Name]],'lojas comp prom'!B:T,19,0) -> PONTO FRIO | K8: =VLOOKUP(Table_Sheet1[[#This Row],[Store Name]],'lojas comp prom'!B:Z,25,0) -> 80 | L8: =VLOOKUP(Table_Sheet1[[#This Row],[Store Name]],'lojas comp prom'!B:S,18,0) -> Shopping Interlagos | M8: =VLOOKUP(Table_Sheet1[[#This Row],[Store Name]],'lojas comp prom'!B:AA,26,0) -> 0 | N8: =VLOOKUP(Table_Sheet1[[#This Row],[Store Name]],'lojas comp prom'!B:L,11,0) -> SPC
A9: 46113.417 | B9: =MOD(Table_Sheet1[[#This Row],[Date/Time]],1) -> 0.41666667 | C9: SPC7612 | D9: PONTO FRIO - AVENIDA INTERLAGOS, 2255 - SHOPPING INTERLAGOS - SPC7612 | E9: Edge60Fusion256_SPC7612 | F9: Edge60Fusion256_SPC7612 | G9: 1 | H9: =VLOOKUP(Table_Sheet1[[#This Row],[Device Name]],'[1]AParelhos_&_LOJAS'!$C:$H,6,0) -> Edge 60 Fusion | I9: =VLOOKUP(Table_Sheet1[[#This Row],[Device Name]],'[1]AParelhos_&_LOJAS'!$C:$I,7,0) -> 256 GB | J9: =VLOOKUP(Table_Sheet1[[#This Row],[Store Name]],'lojas comp prom'!B:T,19,0) -> PONTO FRIO | K9: =VLOOKUP(Table_Sheet1[[#This Row],[Store Name]],'lojas comp prom'!B:Z,25,0) -> 80 | L9: =VLOOKUP(Table_Sheet1[[#This Row],[Store Name]],'lojas comp prom'!B:S,18,0) -> Shopping Interlagos | M9: =VLOOKUP(Table_Sheet1[[#This Row],[Store Name]],'lojas comp prom'!B:AA,26,0) -> 0 | N9: =VLOOKUP(Table_Sheet1[[#This Row],[Store Name]],'lojas comp prom'!B:L,11,0) -> SPC
A10: 46113.417 | B10: =MOD(Table_Sheet1[[#This Row],[Date/Time]],1) -> 0.41666667 | C10: SPC7612 | D10: PONTO FRIO - AVENIDA INTERLAGOS, 2255 - SHOPPING INTERLAGOS - SPC7612 | E10: G05256_SPC7612 | F10: G05256_SPC7612 | G10: 1 | H10: =VLOOKUP(Table_Sheet1[[#This Row],[Device Name]],'[1]AParelhos_&_LOJAS'!$C:$H,6,0) -> G05 | I10: =VLOOKUP(Table_Sheet1[[#This Row],[Device Name]],'[1]AParelhos_&_LOJAS'!$C:$I,7,0) -> 256 GB | J10: =VLOOKUP(Table_Sheet1[[#This Row],[Store Name]],'lojas comp prom'!B:T,19,0) -> PONTO FRIO | K10: =VLOOKUP(Table_Sheet1[[#This Row],[Store Name]],'lojas comp prom'!B:Z,25,0) -> 80 | L10: =VLOOKUP(Table_Sheet1[[#This Row],[Store Name]],'lojas comp prom'!B:S,18,0) -> Shopping Interlagos | M10: =VLOOKUP(Table_Sheet1[[#This Row],[Store Name]],'lojas comp prom'!B:AA,26,0) -> 0 | N10: =VLOOKUP(Table_Sheet1[[#This Row],[Store Name]],'lojas comp prom'!B:L,11,0) -> SPC
A11: 46113.417 | B11: =MOD(Table_Sheet1[[#This Row],[Date/Time]],1) -> 0.41666667 | C11: SPC7612 | D11: PONTO FRIO - AVENIDA INTERLAGOS, 2255 - SHOPPING INTERLAGOS - SPC7612 | E11: G06128_SPC7612 | F11: G06128_SPC7612 | G11: 1 | H11: =VLOOKUP(Table_Sheet1[[#This Row],[Device Name]],'[1]AParelhos_&_LOJAS'!$C:$H,6,0) -> G06 | I11: =VLOOKUP(Table_Sheet1[[#This Row],[Device Name]],'[1]AParelhos_&_LOJAS'!$C:$I,7,0) -> 128 GB | J11: =VLOOKUP(Table_Sheet1[[#This Row],[Store Name]],'lojas comp prom'!B:T,19,0) -> PONTO FRIO | K11: =VLOOKUP(Table_Sheet1[[#This Row],[Store Name]],'lojas comp prom'!B:Z,25,0) -> 80 | L11: =VLOOKUP(Table_Sheet1[[#This Row],[Store Name]],'lojas comp prom'!B:S,18,0) -> Shopping Interlagos | M11: =VLOOKUP(Table_Sheet1[[#This Row],[Store Name]],'lojas comp prom'!B:AA,26,0) -> 0 | N11: =VLOOKUP(Table_Sheet1[[#This Row],[Store Name]],'lojas comp prom'!B:L,11,0) -> SPC
A12: 46113.417 | B12: =MOD(Table_Sheet1[[#This Row],[Date/Time]],1) -> 0.41666667 | C12: SPC7612 | D12: PONTO FRIO - AVENIDA INTERLAGOS, 2255 - SHOPPING INTERLAGOS - SPC7612 | E12: G17128_SPC7612 | F12: G17128_SPC7612 | G12: 1 | H12: =VLOOKUP(Table_Sheet1[[#This Row],[Device Name]],'[1]AParelhos_&_LOJAS'!$C:$H,6,0) -> G17 | I12: =VLOOKUP(Table_Sheet1[[#This Row],[Device Name]],'[1]AParelhos_&_LOJAS'!$C:$I,7,0) -> 128 GB | J12: =VLOOKUP(Table_Sheet1[[#This Row],[Store Name]],'lojas comp prom'!B:T,19,0) -> PONTO FRIO | K12: =VLOOKUP(Table_Sheet1[[#This Row],[Store Name]],'lojas comp prom'!B:Z,25,0) -> 80 | L12: =VLOOKUP(Table_Sheet1[[#This Row],[Store Name]],'lojas comp prom'!B:S,18,0) -> Shopping Interlagos | M12: =VLOOKUP(Table_Sheet1[[#This Row],[Store Name]],'lojas comp prom'!B:AA,26,0) -> 0 | N12: =VLOOKUP(Table_Sheet1[[#This Row],[Store Name]],'lojas comp prom'!B:L,11,0) -> SPC
A13: 46113.417 | B13: =MOD(Table_Sheet1[[#This Row],[Date/Time]],1) -> 0.41666667 | C13: SPC7612 | D13: PONTO FRIO - AVENIDA INTERLAGOS, 2255 - SHOPPING INTERLAGOS - SPC7612 | E13: Razr50Ultra512_SPC7612 | F13: Razr50Ultra512_SPC7612 | G13: 1 | H13: =VLOOKUP(Table_Sheet1[[#This Row],[Device Name]],'[1]AParelhos_&_LOJAS'!$C:$H,6,0) -> Razr 50 Ultra | I13: =VLOOKUP(Table_Sheet1[[#This Row],[Device Name]],'[1]AParelhos_&_LOJAS'!$C:$I,7,0) -> 512 GB | J13: =VLOOKUP(Table_Sheet1[[#This Row],[Store Name]],'lojas comp prom'!B:T,19,0) -> PONTO FRIO | K13: =VLOOKUP(Table_Sheet1[[#This Row],[Store Name]],'lojas comp prom'!B:Z,25,0) -> 80 | L13: =VLOOKUP(Table_Sheet1[[#This Row],[Store Name]],'lojas comp prom'!B:S,18,0) -> Shopping Interlagos | M13: =VLOOKUP(Table_Sheet1[[#This Row],[Store Name]],'lojas comp prom'!B:AA,26,0) -> 0 | N13: =VLOOKUP(Table_Sheet1[[#This Row],[Store Name]],'lojas comp prom'!B:L,11,0) -> SPC
A14: 46113.417 | B14: =MOD(Table_Sheet1[[#This Row],[Date/Time]],1) -> 0.41666667 | C14: SPC7614 | D14: LOJAS AMERICANAS - AVENIDA INTERLAGOS, 2255 - SHOPPING INTERLAGOS - SPC7614 | E14: Edge60Pro256_SPC7614 | F14: Edge60Pro256_SPC7614 | G14: 2 | H14: Edge 60 Pro | I14: 256 GB | J14: =VLOOKUP(Table_Sheet1[[#This Row],[Store Name]],'lojas comp prom'!B:T,19,0) -> LOJAS AMERICANAS | K14: =VLOOKUP(Table_Sheet1[[#This Row],[Store Name]],'lojas comp prom'!B:Z,25,0) -> 80 | L14: =VLOOKUP(Table_Sheet1[[#This Row],[Store Name]],'lojas comp prom'!B:S,18,0) -> Shopping Interlagos | M14: =VLOOKUP(Table_Sheet1[[#This Row],[Store Name]],'lojas comp prom'!B:AA,26,0) -> 0 | N14: =VLOOKUP(Table_Sheet1[[#This Row],[Store Name]],'lojas comp prom'!B:L,11,0) -> SPC
A15: 46113.417 | B15: =MOD(Table_Sheet1[[#This Row],[Date/Time]],1) -> 0.41666667 | C15: SPC7614 | D15: LOJAS AMERICANAS - AVENIDA INTERLAGOS, 2255 - SHOPPING INTERLAGOS - SPC7614 | E15: G35256_SPC7614 | F15: G35256_SPC7614 | G15: 1 | H15: =VLOOKUP(Table_Sheet1[[#This Row],[Device Name]],'[1]AParelhos_&_LOJAS'!$C:$H,6,0) -> G35 | I15: =VLOOKUP(Table_Sheet1[[#This Row],[Device Name]],'[1]AParelhos_&_LOJAS'!$C:$I,7,0) -> 256 GB | J15: =VLOOKUP(Table_Sheet1[[#This Row],[Store Name]],'lojas comp prom'!B:T,19,0) -> LOJAS AMERICANAS | K15: =VLOOKUP(Table_Sheet1[[#This Row],[Store Name]],'lojas comp prom'!B:Z,25,0) -> 80 | L15: =VLOOKUP(Table_Sheet1[[#This Row],[Store Name]],'lojas comp prom'!B:S,18,0) -> Shopping Interlagos | M15: =VLOOKUP(Table_Sheet1[[#This Row],[Store Name]],'lojas comp prom'!B:AA,26,0) -> 0 | N15: =VLOOKUP(Table_Sheet1[[#This Row],[Store Name]],'lojas comp prom'!B:L,11,0) -> SPC
A16: 46113.417 | B16: =MOD(Table_Sheet1[[#This Row],[Date/Time]],1) -> 0.41666667 | C16: SPC7614 | D16: LOJAS AMERICANAS - AVENIDA INTERLAGOS, 2255 - SHOPPING INTERLAGOS - SPC7614 | E16: G86256_SPC7614 | F16: G86256_SPC7614 | G16: 1 | H16: =VLOOKUP(Table_Sheet1[[#This Row],[Device Name]],'[1]AParelhos_&_LOJAS'!$C:$H,6,0) -> G86 | I16: =VLOOKUP(Table_Sheet1[[#This Row],[Device Name]],'[1]AParelhos_&_LOJAS'!$C:$I,7,0) -> 256 GB | J16: =VLOOKUP(Table_Sheet1[[#This Row],[Store Name]],'lojas comp prom'!B:T,19,0) -> LOJAS AMERICANAS | K16: =VLOOKUP(Table_Sheet1[[#This Row],[Store Name]],'lojas comp prom'!B:Z,25,0) -> 80 | L16: =VLOOKUP(Table_Sheet1[[#This Row],[Store Name]],'lojas comp prom'!B:S,18,0) -> Shopping Interlagos | M16: =VLOOKUP(Table_Sheet1[[#This Row],[Store Name]],'lojas comp prom'!B:AA,26,0) -> 0 | N16: =VLOOKUP(Table_Sheet1[[#This Row],[Store Name]],'lojas comp prom'!B:L,11,0) -> SPC
A17: 46113.458 | B17: =MOD(Table_Sheet1[[#This Row],[Date/Time]],1) -> 0.45833333 | C17: SPC11232 | D17: CASAS BAHIA - PRACA FLORIANO PEIXOTO, 38 - ZONA COMERCIAL - SPC11232 | E17: Edge60Fusion256_SPC11232 | F17: Edge60Fusion256_SPC11232 | G17: 4 | H17: =VLOOKUP(Table_Sheet1[[#This Row],[Device Name]],'[1]AParelhos_&_LOJAS'!$C:$H,6,0) -> Edge 60 Fusion | I17: =VLOOKUP(Table_Sheet1[[#This Row],[Device Name]],'[1]AParelhos_&_LOJAS'!$C:$I,7,0) -> 256 GB | J17: =VLOOKUP(Table_Sheet1[[#This Row],[Store Name]],'lojas comp prom'!B:T,19,0) -> CASAS BAHIA | K17: =VLOOKUP(Table_Sheet1[[#This Row],[Store Name]],'lojas comp prom'!B:Z,25,0) -> 80 | L17: =VLOOKUP(Table_Sheet1[[#This Row],[Store Name]],'lojas comp prom'!B:S,18,0) -> Loja De Rua | M17: =VLOOKUP(Table_Sheet1[[#This Row],[Store Name]],'lojas comp prom'!B:AA,26,0) -> 0 | N17: =VLOOKUP(Table_Sheet1[[#This Row],[Store Name]],'lojas comp prom'!B:L,11,0) -> SPC
A18: 46113.458 | B18: =MOD(Table_Sheet1[[#This Row],[Date/Time]],1) -> 0.45833333 | C18: SPC11232 | D18: CASAS BAHIA - PRACA FLORIANO PEIXOTO, 38 - ZONA COMERCIAL - SPC11232 | E18: G06256_SPC11232 | F18: G06256_SPC11232 | G18: 5 | H18: =VLOOKUP(Table_Sheet1[[#This Row],[Device Name]],'[1]AParelhos_&_LOJAS'!$C:$H,6,0) -> G06 | I18: =VLOOKUP(Table_Sheet1[[#This Row],[Device Name]],'[1]AParelhos_&_LOJAS'!$C:$I,7,0) -> 256 GB | J18: =VLOOKUP(Table_Sheet1[[#This Row],[Store Name]],'lojas comp prom'!B:T,19,0) -> CASAS BAHIA | K18: =VLOOKUP(Table_Sheet1[[#This Row],[Store Name]],'lojas comp prom'!B:Z,25,0) -> 80 | L18: =VLOOKUP(Table_Sheet1[[#This Row],[Store Name]],'lojas comp prom'!B:S,18,0) -> Loja De Rua | M18: =VLOOKUP(Table_Sheet1[[#This Row],[Store Name]],'lojas comp prom'!B:AA,26,0) -> 0 | N18: =VLOOKUP(Table_Sheet1[[#This Row],[Store Name]],'lojas comp prom'!B:L,11,0) -> SPC
A19: 46113.458 | B19: =MOD(Table_Sheet1[[#This Row],[Date/Time]],1) -> 0.45833333 | C19: SPC11232 | D19: CASAS BAHIA - PRACA FLORIANO PEIXOTO, 38 - ZONA COMERCIAL - SPC11232 | E19: G86256_SPC11232 | F19: G86256_SPC11232 | G19: 1 | H19: =VLOOKUP(Table_Sheet1[[#This Row],[Device Name]],'[1]AParelhos_&_LOJAS'!$C:$H,6,0) -> G86 | I19: =VLOOKUP(Table_Sheet1[[#This Row],[Device Name]],'[1]AParelhos_&_LOJAS'!$C:$I,7,0) -> 256 GB | J19: =VLOOKUP(Table_Sheet1[[#This Row],[Store Name]],'lojas comp prom'!B:T,19,0) -> CASAS BAHIA | K19: =VLOOKUP(Table_Sheet1[[#This Row],[Store Name]],'lojas comp prom'!B:Z,25,0) -> 80 | L19: =VLOOKUP(Table_Sheet1[[#This Row],[Store Name]],'lojas comp prom'!B:S,18,0) -> Loja De Rua | M19: =VLOOKUP(Table_Sheet1[[#This Row],[Store Name]],'lojas comp prom'!B:AA,26,0) -> 0 | N19: =VLOOKUP(Table_Sheet1[[#This Row],[Store Name]],'lojas comp prom'!B:L,11,0) -> SPC
A20: 46113.458 | B20: =MOD(Table_Sheet1[[#This Row],[Date/Time]],1) -> 0.45833333 | C20: SPC11232 | D20: CASAS BAHIA - PRACA FLORIANO PEIXOTO, 38 - ZONA COMERCIAL - SPC11232 | E20: G86512_SPC11232 | F20: G86512_SPC11232 | G20: 1 | H20: =VLOOKUP(Table_Sheet1[[#This Row],[Device Name]],'[1]AParelhos_&_LOJAS'!$C:$H,6,0) -> G86 | I20: =VLOOKUP(Table_Sheet1[[#This Row],[Device Name]],'[1]AParelhos_&_LOJAS'!$C:$I,7,0) -> 512 GB | J20: =VLOOKUP(Table_Sheet1[[#This Row],[Store Name]],'lojas comp prom'!B:T,19,0) -> CASAS BAHIA | K20: =VLOOKUP(Table_Sheet1[[#This Row],[Store Name]],'lojas comp prom'!B:Z,25,0) -> 80 | L20: =VLOOKUP(Table_Sheet1[[#This Row],[Store Name]],'lojas comp prom'!B:S,18,0) -> Loja De Rua | M20: =VLOOKUP(Table_Sheet1[[#This Row],[Store Name]],'lojas comp prom'!B:AA,26,0) -> 0 | N20: =VLOOKUP(Table_Sheet1[[#This Row],[Store Name]],'lojas comp prom'!B:L,11,0) -> SPC
A21: 46113.458 | B21: =MOD(Table_Sheet1[[#This Row],[Date/Time]],1) -> 0.45833333 | C21: SPC252260 | D21: CASAS BAHIA - AVENIDA EMBAIXADOR MACEDO SOARES, 9175 - SPC252260 | E21: G06128_SPC252260 | F21: G06128_SPC252260 | G21: 3 | H21: =VLOOKUP(Table_Sheet1[[#This Row],[Device Name]],'[1]AParelhos_&_LOJAS'!$C:$H,6,0) -> G06 | I21: =VLOOKUP(Table_Sheet1[[#This Row],[Device Name]],'[1]AParelhos_&_LOJAS'!$C:$I,7,0) -> 128 GB | J21: =VLOOKUP(Table_Sheet1[[#This Row],[Store Name]],'lojas comp prom'!B:T,19,0) -> CASAS BAHIA | K21: =VLOOKUP(Table_Sheet1[[#This Row],[Store Name]],'lojas comp prom'!B:Z,25,0) -> 80 | L21: =VLOOKUP(Table_Sheet1[[#This Row],[Store Name]],'lojas comp prom'!B:S,18,0) -> Loja De Rua | M21: =VLOOKUP(Table_Sheet1[[#This Row],[Store Name]],'lojas comp prom'!B:AA,26,0) -> 0 | N21: =VLOOKUP(Table_Sheet1[[#This Row],[Store Name]],'lojas comp prom'!B:L,11,0) -> SPC
A22: 46113.458 | B22: =MOD(Table_Sheet1[[#This Row],[Date/Time]],1) -> 0.45833333 | C22: SPC252260 | D22: CASAS BAHIA - AVENIDA EMBAIXADOR MACEDO SOARES, 9175 - SPC252260 | E22: G15256_SPC252260 | F22: G15256_SPC252260 | G22: 3 | H22: =VLOOKUP(Table_Sheet1[[#This Row],[Device Name]],'[1]AParelhos_&_LOJAS'!$C:$H,6,0) -> G15 | I22: =VLOOKUP(Table_Sheet1[[#This Row],[Device Name]],'[1]AParelhos_&_LOJAS'!$C:$I,7,0) -> 256 GB | J22: =VLOOKUP(Table_Sheet1[[#This Row],[Store Name]],'lojas comp prom'!B:T,19,0) -> CASAS BAHIA | K22: =VLOOKUP(Table_Sheet1[[#This Row],[Store Name]],'lojas comp prom'!B:Z,25,0) -> 80 | L22: =VLOOKUP(Table_Sheet1[[#This Row],[Store Name]],'lojas comp prom'!B:S,18,0) -> Loja De Rua | M22: =VLOOKUP(Table_Sheet1[[#This Row],[Store Name]],'lojas comp prom'!B:AA,26,0) -> 0 | N22: =VLOOKUP(Table_Sheet1[[#This Row],[Store Name]],'lojas comp prom'!B:L,11,0) -> SPC
A23: 46113.458 | B23: =MOD(Table_Sheet1[[#This Row],[Date/Time]],1) -> 0.45833333 | C23: SPC252260 | D23: CASAS BAHIA - AVENIDA EMBAIXADOR MACEDO SOARES, 9175 - SPC252260 | E23: G56256_SPC252260 | F23: G56256_SPC252260 | G23: 1 | H23: =VLOOKUP(Table_Sheet1[[#This Row],[Device Name]],'[1]AParelhos_&_LOJAS'!$C:$H,6,0) -> G56 | I23: =VLOOKUP(Table_Sheet1[[#This Row],[Device Name]],'[1]AParelhos_&_LOJAS'!$C:$I,7,0) -> 256 GB | J23: =VLOOKUP(Table_Sheet1[[#This Row],[Store Name]],'lojas comp prom'!B:T,19,0) -> CASAS BAHIA | K23: =VLOOKUP(Table_Sheet1[[#This Row],[Store Name]],'lojas comp prom'!B:Z,25,0) -> 80 | L23: =VLOOKUP(Table_Sheet1[[#This Row],[Store Name]],'lojas comp prom'!B:S,18,0) -> Loja De Rua | M23: =VLOOKUP(Table_Sheet1[[#This Row],[Store Name]],'lojas comp prom'!B:AA,26,0) -> 0 | N23: =VLOOKUP(Table_Sheet1[[#This Row],[Store Name]],'lojas comp prom'!B:L,11,0) -> SPC
A24: 46113.458 | B24: =MOD(Table_Sheet1[[#This Row],[Date/Time]],1) -> 0.45833333 | C24: SPC252260 | D24: CASAS BAHIA - AVENIDA EMBAIXADOR MACEDO SOARES, 9175 - SPC252260 | E24: G75256_SPC252260 | F24: G75256_SPC252260 | G24: 3 | H24: =VLOOKUP(Table_Sheet1[[#This Row],[Device Name]],'[1]AParelhos_&_LOJAS'!$C:$H,6,0) -> G75 | I24: =VLOOKUP(Table_Sheet1[[#This Row],[Device Name]],'[1]AParelhos_&_LOJAS'!$C:$I,7,0) -> 256 GB | J24: =VLOOKUP(Table_Sheet1[[#This Row],[Store Name]],'lojas comp prom'!B:T,19,0) -> CASAS BAHIA | K24: =VLOOKUP(Table_Sheet1[[#This Row],[Store Name]],'lojas comp prom'!B:Z,25,0) -> 80 | L24: =VLOOKUP(Table_Sheet1[[#This Row],[Store Name]],'lojas comp prom'!B:S,18,0) -> Loja De Rua | M24: =VLOOKUP(Table_Sheet1[[#This Row],[Store Name]],'lojas comp prom'!B:AA,26,0) -> 0 | N24: =VLOOKUP(Table_Sheet1[[#This Row],[Store Name]],'lojas comp prom'!B:L,11,0) -> SPC
A25: 46113.458 | B25: =MOD(Table_Sheet1[[#This Row],[Date/Time]],1) -> 0.45833333 | C25: SPC252260 | D25: CASAS BAHIA - AVENIDA EMBAIXADOR MACEDO SOARES, 9175 - SPC252260 | E25: G86256_SPC252260 | F25: G86256_SPC252260 | G25: 3 | H25: =VLOOKUP(Table_Sheet1[[#This Row],[Device Name]],'[1]AParelhos_&_LOJAS'!$C:$H,6,0) -> G86 | I25: =VLOOKUP(Table_Sheet1[[#This Row],[Device Name]],'[1]AParelhos_&_LOJAS'!$C:$I,7,0) -> 256 GB | J25: =VLOOKUP(Table_Sheet1[[#This Row],[Store Name]],'lojas comp prom'!B:T,19,0) -> CASAS BAHIA | K25: =VLOOKUP(Table_Sheet1[[#This Row],[Store Name]],'lojas comp prom'!B:Z,25,0) -> 80 | L25: =VLOOKUP(Table_Sheet1[[#This Row],[Store Name]],'lojas comp prom'!B:S,18,0) -> Loja De Rua | M25: =VLOOKUP(Table_Sheet1[[#This Row],[Store Name]],'lojas comp prom'!B:AA,26,0) -> 0 | N25: =VLOOKUP(Table_Sheet1[[#This Row],[Store Name]],'lojas comp prom'!B:L,11,0) -> SPC
A26: 46113.458 | B26: =MOD(Table_Sheet1[[#This Row],[Date/Time]],1) -> 0.45833333 | C26: SPC287350 | D26: CASAS BAHIA - AVENIDA NACOES UNIDAS, 12995 - SPC287350 | E26: Edge60Pro256_SPC287350 | F26: Edge60Pro256_SPC287350 | G26: 2 | H26: Edge 60 Pro | I26: 256 GB | J26: =VLOOKUP(Table_Sheet1[[#This Row],[Store Name]],'lojas comp prom'!B:T,19,0) -> CASAS BAHIA | K26: =VLOOKUP(Table_Sheet1[[#This Row],[Store Name]],'lojas comp prom'!B:Z,25,0) -> 80 | L26: =VLOOKUP(Table_Sheet1[[#This Row],[Store Name]],'lojas comp prom'!B:S,18,0) -> Loja De Rua | M26: =VLOOKUP(Table_Sheet1[[#This Row],[Store Name]],'lojas comp prom'!B:AA,26,0) -> 0 | N26: =VLOOKUP(Table_Sheet1[[#This Row],[Store Name]],'lojas comp prom'!B:L,11,0) -> SPC
A27: 46113.458 | B27: =MOD(Table_Sheet1[[#This Row],[Date/Time]],1) -> 0.45833333 | C27: SPC7614 | D27: LOJAS AMERICANAS - AVENIDA INTERLAGOS, 2255 - SHOPPING INTERLAGOS - SPC7614 | E27: G67256_SPC7614 | F27: G67256_SPC7614 | G27: 1 | H27: =VLOOKUP(Table_Sheet1[[#This Row],[Device Name]],'[1]AParelhos_&_LOJAS'!$C:$H,6,0) -> G67 | I27: =VLOOKUP(Table_Sheet1[[#This Row],[Device Name]],'[1]AParelhos_&_LOJAS'!$C:$I,7,0) -> 256 GB | J27: =VLOOKUP(Table_Sheet1[[#This Row],[Store Name]],'lojas comp prom'!B:T,19,0) -> LOJAS AMERICANAS | K27: =VLOOKUP(Table_Sheet1[[#This Row],[Store Name]],'lojas comp prom'!B:Z,25,0) -> 80 | L27: =VLOOKUP(Table_Sheet1[[#This Row],[Store Name]],'lojas comp prom'!B:S,18,0) -> Shopping Interlagos | M27: =VLOOKUP(Table_Sheet1[[#This Row],[Store Name]],'lojas comp prom'!B:AA,26,0) -> 0 | N27: =VLOOKUP(Table_Sheet1[[#This Row],[Store Name]],'lojas comp prom'!B:L,11,0) -> SPC
A28: 46113.458 | B28: =MOD(Table_Sheet1[[#This Row],[Date/Time]],1) -> 0.45833333 | C28: SPC7614 | D28: LOJAS AMERICANAS - AVENIDA INTERLAGOS, 2255 - SHOPPING INTERLAGOS - SPC7614 | E28: G77256_SPC7614 | F28: G77256_SPC7614 | G28: 1 | H28: =VLOOKUP(Table_Sheet1[[#This Row],[Device Name]],'[1]AParelhos_&_LOJAS'!$C:$H,6,0) -> G77 | I28: =VLOOKUP(Table_Sheet1[[#This Row],[Device Name]],'[1]AParelhos_&_LOJAS'!$C:$I,7,0) -> 256 GB | J28: =VLOOKUP(Table_Sheet1[[#This Row],[Store Name]],'lojas comp prom'!B:T,19,0) -> LOJAS AMERICANAS | K28: =VLOOKUP(Table_Sheet1[[#This Row],[Store Name]],'lojas comp prom'!B:Z,25,0) -> 80 | L28: =VLOOKUP(Table_Sheet1[[#This Row],[Store Name]],'lojas comp prom'!B:S,18,0) -> Shopping Interlagos | M28: =VLOOKUP(Table_Sheet1[[#This Row],[Store Name]],'lojas comp prom'!B:AA,26,0) -> 0 | N28: =VLOOKUP(Table_Sheet1[[#This Row],[Store Name]],'lojas comp prom'!B:L,11,0) -> SPC
A29: 46113.5 | B29: =MOD(Table_Sheet1[[#This Row],[Date/Time]],1) -> 0.5 | C29: SPC11232 | D29: CASAS BAHIA - PRACA FLORIANO PEIXOTO, 38 - ZONA COMERCIAL - SPC11232 | E29: Edge60Fusion256_SPC11232 | F29: Edge60Fusion256_SPC11232 | G29: 1 | H29: =VLOOKUP(Table_Sheet1[[#This Row],[Device Name]],'[1]AParelhos_&_LOJAS'!$C:$H,6,0) -> Edge 60 Fusion | I29: =VLOOKUP(Table_Sheet1[[#This Row],[Device Name]],'[1]AParelhos_&_LOJAS'!$C:$I,7,0) -> 256 GB | J29: =VLOOKUP(Table_Sheet1[[#This Row],[Store Name]],'lojas comp prom'!B:T,19,0) -> CASAS BAHIA | K29: =VLOOKUP(Table_Sheet1[[#This Row],[Store Name]],'lojas comp prom'!B:Z,25,0) -> 80 | L29: =VLOOKUP(Table_Sheet1[[#This Row],[Store Name]],'lojas comp prom'!B:S,18,0) -> Loja De Rua | M29: =VLOOKUP(Table_Sheet1[[#This Row],[Store Name]],'lojas comp prom'!B:AA,26,0) -> 0 | N29: =VLOOKUP(Table_Sheet1[[#This Row],[Store Name]],'lojas comp prom'!B:L,11,0) -> SPC
A30: 46113.5 | B30: =MOD(Table_Sheet1[[#This Row],[Date/Time]],1) -> 0.5 | C30: SPC11232 | D30: CASAS BAHIA - PRACA FLORIANO PEIXOTO, 38 - ZONA COMERCIAL - SPC11232 | E30: Edge60Pro256_SPC11232_2 | F30: Edge60Pro256_SPC11232_2 | G30: 2 | H30: Edge 60 Pro | I30: 256 GB | J30: =VLOOKUP(Table_Sheet1[[#This Row],[Store Name]],'lojas comp prom'!B:T,19,0) -> CASAS BAHIA | K30: =VLOOKUP(Table_Sheet1[[#This Row],[Store Name]],'lojas comp prom'!B:Z,25,0) -> 80 | L30: =VLOOKUP(Table_Sheet1[[#This Row],[Store Name]],'lojas comp prom'!B:S,18,0) -> Loja De Rua | M30: =VLOOKUP(Table_Sheet1[[#This Row],[Store Name]],'lojas comp prom'!B:AA,26,0) -> 0 | N30: =VLOOKUP(Table_Sheet1[[#This Row],[Store Name]],'lojas comp prom'!B:L,11,0) -> SPC
A31: 46113.5 | B31: =MOD(Table_Sheet1[[#This Row],[Date/Time]],1) -> 0.5 | C31: SPC11232 | D31: CASAS BAHIA - PRACA FLORIANO PEIXOTO, 38 - ZONA COMERCIAL - SPC11232 | E31: G06128_SPC11232 | F31: G06128_SPC11232 | G31: 1 | H31: =VLOOKUP(Table_Sheet1[[#This Row],[Device Name]],'[1]AParelhos_&_LOJAS'!$C:$H,6,0) -> G06 | I31: =VLOOKUP(Table_Sheet1[[#This Row],[Device Name]],'[1]AParelhos_&_LOJAS'!$C:$I,7,0) -> 128 GB | J31: =VLOOKUP(Table_Sheet1[[#This Row],[Store Name]],'lojas comp prom'!B:T,19,0) -> CASAS BAHIA | K31: =VLOOKUP(Table_Sheet1[[#This Row],[Store Name]],'lojas comp prom'!B:Z,25,0) -> 80 | L31: =VLOOKUP(Table_Sheet1[[#This Row],[Store Name]],'lojas comp prom'!B:S,18,0) -> Loja De Rua | M31: =VLOOKUP(Table_Sheet1[[#This Row],[Store Name]],'lojas comp prom'!B:AA,26,0) -> 0 | N31: =VLOOKUP(Table_Sheet1[[#This Row],[Store Name]],'lojas comp prom'!B:L,11,0) -> SPC
A32: 46113.5 | B32: =MOD(Table_Sheet1[[#This Row],[Date/Time]],1) -> 0.5 | C32: SPC11232 | D32: CASAS BAHIA - PRACA FLORIANO PEIXOTO, 38 - ZONA COMERCIAL - SPC11232 | E32: G06256_SPC11232 | F32: G06256_SPC11232 | G32: 6 | H32: =VLOOKUP(Table_Sheet1[[#This Row],[Device Name]],'[1]AParelhos_&_LOJAS'!$C:$H,6,0) -> G06 | I32: =VLOOKUP(Table_Sheet1[[#This Row],[Device Name]],'[1]AParelhos_&_LOJAS'!$C:$I,7,0) -> 256 GB | J32: =VLOOKUP(Table_Sheet1[[#This Row],[Store Name]],'lojas comp prom'!B:T,19,0) -> CASAS BAHIA | K32: =VLOOKUP(Table_Sheet1[[#This Row],[Store Name]],'lojas comp prom'!B:Z,25,0) -> 80 | L32: =VLOOKUP(Table_Sheet1[[#This Row],[Store Name]],'lojas comp prom'!B:S,18,0) -> Loja De Rua | M32: =VLOOKUP(Table_Sheet1[[#This Row],[Store Name]],'lojas comp prom'!B:AA,26,0) -> 0 | N32: =VLOOKUP(Table_Sheet1[[#This Row],[Store Name]],'lojas comp prom'!B:L,11,0) -> SPC
A33: 46113.5 | B33: =MOD(Table_Sheet1[[#This Row],[Date/Time]],1) -> 0.5 | C33: SPC11232 | D33: CASAS BAHIA - PRACA FLORIANO PEIXOTO, 38 - ZONA COMERCIAL - SPC11232 | E33: G17128_SPC11232 | F33: G17128_SPC11232 | G33: 1 | H33: =VLOOKUP(Table_Sheet1[[#This Row],[Device Name]],'[1]AParelhos_&_LOJAS'!$C:$H,6,0) -> G17 | I33: =VLOOKUP(Table_Sheet1[[#This Row],[Device Name]],'[1]AParelhos_&_LOJAS'!$C:$I,7,0) -> 128 GB | J33: =VLOOKUP(Table_Sheet1[[#This Row],[Store Name]],'lojas comp prom'!B:T,19,0) -> CASAS BAHIA | K33: =VLOOKUP(Table_Sheet1[[#This Row],[Store Name]],'lojas comp prom'!B:Z,25,0) -> 80 | L33: =VLOOKUP(Table_Sheet1[[#This Row],[Store Name]],'lojas comp prom'!B:S,18,0) -> Loja De Rua | M33: =VLOOKUP(Table_Sheet1[[#This Row],[Store Name]],'lojas comp prom'!B:AA,26,0) -> 0 | N33: =VLOOKUP(Table_Sheet1[[#This Row],[Store Name]],'lojas comp prom'!B:L,11,0) -> SPC
A34: 46113.5 | B34: =MOD(Table_Sheet1[[#This Row],[Date/Time]],1) -> 0.5 | C34: SPC11232 | D34: CASAS BAHIA - PRACA FLORIANO PEIXOTO, 38 - ZONA COMERCIAL - SPC11232 | E34: G86256_SPC11232 | F34: G86256_SPC11232 | G34: 4 | H34: =VLOOKUP(Table_Sheet1[[#This Row],[Device Name]],'[1]AParelhos_&_LOJAS'!$C:$H,6,0) -> G86 | I34: =VLOOKUP(Table_Sheet1[[#This Row],[Device Name]],'[1]AParelhos_&_LOJAS'!$C:$I,7,0) -> 256 GB | J34: =VLOOKUP(Table_Sheet1[[#This Row],[Store Name]],'lojas comp prom'!B:T,19,0) -> CASAS BAHIA | K34: =VLOOKUP(Table_Sheet1[[#This Row],[Store Name]],'lojas comp prom'!B:Z,25,0) -> 80 | L34: =VLOOKUP(Table_Sheet1[[#This Row],[Store Name]],'lojas comp prom'!B:S,18,0) -> Loja De Rua | M34: =VLOOKUP(Table_Sheet1[[#This Row],[Store Name]],'lojas comp prom'!B:AA,26,0) -> 0 | N34: =VLOOKUP(Table_Sheet1[[#This Row],[Store Name]],'lojas comp prom'!B:L,11,0) -> SPC
A35: 46113.5 | B35: =MOD(Table_Sheet1[[#This Row],[Date/Time]],1) -> 0.5 | C35: SPC11232 | D35: CASAS BAHIA - PRACA FLORIANO PEIXOTO, 38 - ZONA COMERCIAL - SPC11232 | E35: G86512_SPC11232 | F35: G86512_SPC11232 | G35: 1 | H35: =VLOOKUP(Table_Sheet1[[#This Row],[Device Name]],'[1]AParelhos_&_LOJAS'!$C:$H,6,0) -> G86 | I35: =VLOOKUP(Table_Sheet1[[#This Row],[Device Name]],'[1]AParelhos_&_LOJAS'!$C:$I,7,0) -> 512 GB | J35: =VLOOKUP(Table_Sheet1[[#This Row],[Store Name]],'lojas comp prom'!B:T,19,0) -> CASAS BAHIA | K35: =VLOOKUP(Table_Sheet1[[#This Row],[Store Name]],'lojas comp prom'!B:Z,25,0) -> 80 | L35: =VLOOKUP(Table_Sheet1[[#This Row],[Store Name]],'lojas comp prom'!B:S,18,0) -> Loja De Rua | M35: =VLOOKUP(Table_Sheet1[[#This Row],[Store Name]],'lojas comp prom'!B:AA,26,0) -> 0 | N35: =VLOOKUP(Table_Sheet1[[#This Row],[Store Name]],'lojas comp prom'!B:L,11,0) -> SPC
A36: 46113.5 | B36: =MOD(Table_Sheet1[[#This Row],[Date/Time]],1) -> 0.5 | C36: SPC252260 | D36: CASAS BAHIA - AVENIDA EMBAIXADOR MACEDO SOARES, 9175 - SPC252260 | E36: Edge60256GB_SPC252260 | F36: Edge60256GB_SPC252260 | G36: 3 | H36: Edge 60 Pro | I36: 256 GB | J36: =VLOOKUP(Table_Sheet1[[#This Row],[Store Name]],'lojas comp prom'!B:T,19,0) -> CASAS BAHIA | K36: =VLOOKUP(Table_Sheet1[[#This Row],[Store Name]],'lojas comp prom'!B:Z,25,0) -> 80 | L36: =VLOOKUP(Table_Sheet1[[#This Row],[Store Name]],'lojas comp prom'!B:S,18,0) -> Loja De Rua | M36: =VLOOKUP(Table_Sheet1[[#This Row],[Store Name]],'lojas comp prom'!B:AA,26,0) -> 0 | N36: =VLOOKUP(Table_Sheet1[[#This Row],[Store Name]],'lojas comp prom'!B:L,11,0) -> SPC
A37: 46113.5 | B37: =MOD(Table_Sheet1[[#This Row],[Date/Time]],1) -> 0.5 | C37: SPC252260 | D37: CASAS BAHIA - AVENIDA EMBAIXADOR MACEDO SOARES, 9175 - SPC252260 | E37: Edge60Pro256_SPC252260 | F37: Edge60Pro256_SPC252260 | G37: 2 | H37: Edge 60 Pro | I37: 256 GB | J37: =VLOOKUP(Table_Sheet1[[#This Row],[Store Name]],'lojas comp prom'!B:T,19,0) -> CASAS BAHIA | K37: =VLOOKUP(Table_Sheet1[[#This Row],[Store Name]],'lojas comp prom'!B:Z,25,0) -> 80 | L37: =VLOOKUP(Table_Sheet1[[#This Row],[Store Name]],'lojas comp prom'!B:S,18,0) -> Loja De Rua | M37: =VLOOKUP(Table_Sheet1[[#This Row],[Store Name]],'lojas comp prom'!B:AA,26,0) -> 0 | N37: =VLOOKUP(Table_Sheet1[[#This Row],[Store Name]],'lojas comp prom'!B:L,11,0) -> SPC
A38: 46113.5 | B38: =MOD(Table_Sheet1[[#This Row],[Date/Time]],1) -> 0.5 | C38: SPC252260 | D38: CASAS BAHIA - AVENIDA EMBAIXADOR MACEDO SOARES, 9175 - SPC252260 | E38: G05128_SPC252260 | F38: G05128_SPC252260 | G38: 2 | H38: =VLOOKUP(Table_Sheet1[[#This Row],[Device Name]],'[1]AParelhos_&_LOJAS'!$C:$H,6,0) -> G05 | I38: =VLOOKUP(Table_Sheet1[[#This Row],[Device Name]],'[1]AParelhos_&_LOJAS'!$C:$I,7,0) -> 128 GB | J38: =VLOOKUP(Table_Sheet1[[#This Row],[Store Name]],'lojas comp prom'!B:T,19,0) -> CASAS BAHIA | K38: =VLOOKUP(Table_Sheet1[[#This Row],[Store Name]],'lojas comp prom'!B:Z,25,0) -> 80 | L38: =VLOOKUP(Table_Sheet1[[#This Row],[Store Name]],'lojas comp prom'!B:S,18,0) -> Loja De Rua | M38: =VLOOKUP(Table_Sheet1[[#This Row],[Store Name]],'lojas comp prom'!B:AA,26,0) -> 0 | N38: =VLOOKUP(Table_Sheet1[[#This Row],[Store Name]],'lojas comp prom'!B:L,11,0) -> SPC
A39: 46113.5 | B39: =MOD(Table_Sheet1[[#This Row],[Date/Time]],1) -> 0.5 | C39: SPC252260 | D39: CASAS BAHIA - AVENIDA EMBAIXADOR MACEDO SOARES, 9175 - SPC252260 | E39: G05256_SPC252260 | F39: G05256_SPC252260 | G39: 10 | H39: =VLOOKUP(Table_Sheet1[[#This Row],[Device Name]],'[1]AParelhos_&_LOJAS'!$C:$H,6,0) -> G05 | I39: =VLOOKUP(Table_Sheet1[[#This Row],[Device Name]],'[1]AParelhos_&_LOJAS'!$C:$I,7,0) -> 256 GB | J39: =VLOOKUP(Table_Sheet1[[#This Row],[Store Name]],'lojas comp prom'!B:T,19,0) -> CASAS BAHIA | K39: =VLOOKUP(Table_Sheet1[[#This Row],[Store Name]],'lojas comp prom'!B:Z,25,0) -> 80 | L39: =VLOOKUP(Table_Sheet1[[#This Row],[Store Name]],'lojas comp prom'!B:S,18,0) -> Loja De Rua | M39: =VLOOKUP(Table_Sheet1[[#This Row],[Store Name]],'lojas comp prom'!B:AA,26,0) -> 0 | N39: =VLOOKUP(Table_Sheet1[[#This Row],[Store Name]],'lojas comp prom'!B:L,11,0) -> SPC
A40: 46113.5 | B40: =MOD(Table_Sheet1[[#This Row],[Date/Time]],1) -> 0.5 | C40: SPC252260 | D40: CASAS BAHIA - AVENIDA EMBAIXADOR MACEDO SOARES, 9175 - SPC252260 | E40: G06128_SPC252260 | F40: G06128_SPC252260 | G40: 3 | H40: =VLOOKUP(Table_Sheet1[[#This Row],[Device Name]],'[1]AParelhos_&_LOJAS'!$C:$H,6,0) -> G06 | I40: =VLOOKUP(Table_Sheet1[[#This Row],[Device Name]],'[1]AParelhos_&_LOJAS'!$C:$I,7,0) -> 128 GB | J40: =VLOOKUP(Table_Sheet1[[#This Row],[Store Name]],'lojas comp prom'!B:T,19,0) -> CASAS BAHIA | K40: =VLOOKUP(Table_Sheet1[[#This Row],[Store Name]],'lojas comp prom'!B:Z,25,0) -> 80 | L40: =VLOOKUP(Table_Sheet1[[#This Row],[Store Name]],'lojas comp prom'!B:S,18,0) -> Loja De Rua | M40: =VLOOKUP(Table_Sheet1[[#This Row],[Store Name]],'lojas comp prom'!B:AA,26,0) -> 0 | N40: =VLOOKUP(Table_Sheet1[[#This Row],[Store Name]],'lojas comp prom'!B:L,11,0) -> SPC
...

Sheet lojas comp prom
A1: id_pdv | B1: ponto_de_venda | C1: endereco | D1: numero | E1: complemento | F1: bairro | G1: cidade | H1: uf | I1: cep | J1: coordenadas | K1: microrregional | L1: macrorregional | M1: cod_spar | N1: ativo | O1: cnpj | P1: id_ext_pdv | Q1: rede_ | R1: Coluna1 | S1: centro_comercial | T1: campo_extra | U1: tipo_de_loja | V1: rede | W1: bandeira | X1: Total Atendimentos 3 meses | Y1: Cluster EVER | Z1: 80/20 | AA1: visibilidade | AB1: Intersec
A2: 21875 | B2: CLARO - AVENIDA JOAO WALLIG, 1800 - SHOPPING IGUATEMI PORTO ALEGRE - SUL7372 | C2: AVENIDA JOAO WALLIG | D2: 1800 | E2: LOJA 1246,1ºPISO | F2: PASSO D'AREIA | G2: Porto Alegre | H2: RS | I2: 91349900 | J2: -30.024227 , -51.161819 | K2: SUL 2 | L2: SUL | M2: SUL7372 | N2: Sim | O2: 40432544009101 | P2: 5106 | Q2: CLARO | S2: Shopping Iguatemi Porto Alegre | T2: CLARO LP | U2: OPERADORA | V2: CLARO | W2: CLARO LP | X2: 100 | Y2: A | Z2: 80 | AA2: 1 | AB2: 1
A3: 21378 | B3: CASAS BAHIA - AVENIDA JOSE PINHEIRO BORGES, S/N - SHOPPING METRO ITAQUERA - SPC7759 | C3: AVENIDA JOSE PINHEIRO BORGES | D3: S/N | E3: LOJAS 129 E 130,T | F3: ITAQUERA | G3: São Paulo | H3: SP | I3: 8220385 | J3: -23.540546 , -46.470375 | K3: SPC 7 | L3: SPC | M3: SPC7759 | N3: Sim | O3: 33041260115573 | P3: 1172 | Q3: VAREJO | S3: Shopping Itaquera | T3: CASAS BAHIA | U3: VAREJO | V3: VIA VAREJO | W3: CASAS BAHIA | X3: 78 | Y3: A | Z3: 80 | AA3: 0 | AB3: 0
A4: 23716 | B4: MAGAZINE LUIZA - AVENIDA REPLUBICA DO LIBANO, 251 - SHOPPING RIO MAR - NE7945 | C4: AVENIDA REPUBLICA DO LIBANO | D4: 251 | E4: LOJA 1099 E 1100 | F4: PINA | G4: Recife | H4: PE | I4: 51110160 | J4: -8.086065 , -34.895043 | K4: NE 1 | L4: NE | M4: NE7945 | N4: Sim | O4: 47960950088207 | P4: 713 | Q4: VAREJO | S4: Shopping Rio Mar | T4: MAGAZINE LUIZA | U4: VAREJO | V4: MAGAZINE LUIZA | W4: MAGAZINE LUIZA | X4: 77 | Y4: A | Z4: 80 | AA4: 1 | AB4: 1
A5: 23935 | B5: MAGAZINE LUIZA - RUA PADRE CARAPUCEIRO, 777 - SHOPPING RECIFE - NE5959 | C5: RUA CARAPUCEIRO | D5: 777 | E5: LOJAS 29 E 30 A | F5: BOA VIAGEM | G5: Recife | H5: PE | I5: 51020900 | J5: -8.119827 , -34.905079 | K5: NE 1 | L5: NE | M5: NE5959 | N5: Sim | O5: 47960950080214 | P5: 851 | Q5: VAREJO | S5: Shopping Recife | T5: MAGAZINE LUIZA | U5: VAREJO | V5: MAGAZINE LUIZA | W5: MAGAZINE LUIZA | X5: 77 | Y5: A | Z5: 80 | AA5: 1 | AB5: 1
A6: 21450 | B6: CASAS BAHIA - AVENIDA REPLUBICA DO LIBANO, 251 - SHOPPING RIO MAR - NE6897 | C6: AVENIDA REPUBLICA DO LIBANO | D6: 251 | F6: PINA | G6: Recife | H6: PE | I6: 51110160 | J6: -8.085789 , -34.89513 | K6: NE 1 | L6: NE | M6: NE6897 | N6: Sim | O6: 33041260094207 | P6: 1685 | Q6: VAREJO | S6: Shopping Rio Mar | T6: CASAS BAHIA | U6: VAREJO | V6: VIA VAREJO | W6: CASAS BAHIA | X6: 74 | Y6: A | Z6: 80 | AA6: 1 | AB6: 1
A7: 23741 | B7: MAGAZINE LUIZA - AVENIDA TANCREDO NEVES, 148 - SHOPPING DA BAHIA - NE40438 | C7: AVENIDA TANCREDO NEVES | D7: 148 | E7: LOJAS 53 A 56- 62/63 | F7: CAMINHO DAS ARVORES | G7: Salvador | H7: BA | I7: 41820908 | J7: -12.981811 , -38.464088 | K7: NE 4 | L7: NE | M7: NE40438 | N7: Sim | O7: 47960950076101 | P7: 747 | Q7: VAREJO | S7: Shopping Da Bahia | T7: MAGAZINE LUIZA | U7: VAREJO | V7: MAGAZINE LUIZA | W7: MAGAZINE LUIZA | X7: 74 | Y7: A | Z7: 80 | AA7: 1 | AB7: 1
A8: 21284 | B8: CASAS BAHIA - AVENIDA ARICANDUVA, 5555 (LOJA 2) - SHOPPING ARICANDUVA - SPC22892 | C8: AVENIDA ARICANDUVA | D8: 5555 | E8: LOJA 30 | F8: VILA MATILDE | G8: São Paulo | H8: SP | I8: 3527900 | J8: -23.565256 , -46.503628 | K8: SPC 7 | L8: SPC | M8: SPC22892 | N8: Sim | O8: 33041260210991 | P8: 3100 | Q8: VAREJO | S8: Shopping Aricanduva | T8: CASAS BAHIA | U8: VAREJO | V8: VIA VAREJO | W8: CASAS BAHIA | X8: 72 | Y8: A | Z8: 80 | AA8: 0 | AB8: 0
A9: 26350 | B9: CASAS BAHIA - RUA ERNEST RENAN, 1032 - ZONA COMERCIAL - SPC11263 | C9: RUA ERNEST RENAN | D9: 1032 | F9: PARAISOPOLIS | G9: São Paulo | H9: SP | I9: 5659020 | J9: -23.6140632 , -46.7244753 | K9: SPC 8 | L9: SPC | M9: SPC11263 | N9: Sim | O9: 33041260101785 | P9: 1294 | Q9: VAREJO | S9: Loja De Rua | T9: CASAS BAHIA | U9: VAREJO | V9: VIA VAREJO | W9: CASAS BAHIA | X9: 72 | Y9: A | Z9: 80 | AA9: 0 | AB9: 0
A10: 112869 | B10: MAGAZINE LUIZA - QUADRA CL 214 LOTE B, S/N - MGCO258120 | C10: QUADRA CL 214 LOTE B | D10: S/N | E10: LOJA 1 E 2 | F10: SANTA MARIA | G10: Brasília | H10: DF | I10: 72544220 | J10: -16.0071534,-48.0015546 | K10: MG CO 1 | L10: MG CO | M10: MGCO258120 | N10: Sim | O10: 47960950143070 | P10: 1164 | Q10: VAREJO | S10: Loja De Rua | T10: MAGAZINE LUIZA | U10: VAREJO | V10: MAGAZINE LUIZA | W10: MAGAZINE LUIZA | X10: 72 | Y10: A | Z10: 80 | AA10: 0 | AB10: 0
A11: 24708 | B11: PONTO FRIO - RUA CAPITAO TIAGO LUZ, 146 - ZONA COMERCIAL - SPC7621 | C11: PRACA FLORIANO PEIXOTO | D11: 146 | E11: FILIAL 725 | F11: SANTO AMARO | G11: São Paulo | H11: SP | I11: 4751030 | J11: -23.651297 , -46.707901 | K11: SPC 8 | L11: SPC | M11: SPC7621 | N11: Sim | O11: 33041260030829 | P11: 275 | Q11: VAREJO | S11: Loja De Rua | T11: PONTO FRIO | U11: VAREJO | V11: VIA VAREJO | W11: PONTO FRIO | X11: 72 | Y11: A | Z11: 80 | AA11: 0 | AB11: 0
A12: 25438 | B12: VIVO - AVENIDA JOAO WALLIG, 1800 - SHOPPING IGUATEMI PORTO ALEGRE - SUL6219 | C12: AVENIDA JOAO WALLIG | D12: 1800 | E12: LOJA 147 PISO 1 PART | F12: PASSO D'AREIA | G12: Porto Alegre | H12: RS | I12: 91340001 | J12: -30.024227 , -51.161819 | K12: SUL 2 | L12: SUL | M12: SUL6219 | N12: Sim | O12: 2558157035039 | P12: LOJA IGUATEMI RS | Q12: VIVO | S12: Shopping Iguatemi Porto Alegre | T12: VIVO LP | U12: OPERADORA | V12: VIVO | W12: VIVO LP | X12: 72 | Y12: A | Z12: 20 | AA12: 1 | AB12: 0
A13: 21475 | B13: CASAS BAHIA - AVENIDA TANCREDO NEVES, 148 (LOJA 1) - SHOPPING DA BAHIA - NE7413 | C13: AVENIDA TANCREDO NEVES | D13: 148 | E13: LOJA 2A,9 E 10,QD D | F13: CAMINHO DAS ARVORES | G13: Salvador | H13: BA | I13: 41820908 | J13: -12.981811 , -38.464088 | K13: NE 4 | L13: NE | M13: NE7413 | N13: Sim | O13: 33041260138433 | P13: 1499 | Q13: VAREJO | S13: Shopping Da Bahia | T13: CASAS BAHIA | U13: VAREJO | V13: VIA VAREJO | W13: CASAS BAHIA | X13: 71 | Y13: A | Z13: 80 | AA13: 1 | AB13: 1
A14: 23841 | B14: MAGAZINE LUIZA - RUA CAPITAO TIAGO LUZ, 139 - ZONA COMERCIAL - SPC7618 | C14: RUA CAPITAO TIAGO LUZ | D14: 121 | E14: 125 | F14: SANTO AMARO | G14: São Paulo | H14: SP | I14: 4751010 | J14: -23.653011 , -46.706856 | K14: SPC 8 | L14: SPC | M14: SPC7618 | N14: Sim | O14: 47960950070928 | P14: 958 | Q14: VAREJO | S14: Loja De Rua | T14: MAGAZINE LUIZA | U14: VAREJO | V14: MAGAZINE LUIZA | W14: MAGAZINE LUIZA | X14: 71 | Y14: A | Z14: 80 | AA14: 0 | AB14: 0
A15: 23588 | B15: MAGAZINE LUIZA - AVENIDA BERNADO VIEIRA, 3775 - MIDWAY - NE79537 | C15: AVENIDA BERNARDO VIEIRA | D15: 3775 | E15: LOJA 120A PISO L1 | F15: TIROL | G15: Natal | H15: RN | I15: 59015900 | J15: -5.811385 , -35.206245 | K15: NE 2 | L15: NE | M15: NE79537 | N15: Sim | O15: 47960950101157 | P15: 1204 | Q15: VAREJO | S15: Shopping Midway Mall | T15: MAGAZINE LUIZA | U15: VAREJO | V15: MAGAZINE LUIZA | W15: MAGAZINE LUIZA | X15: 71 | Y15: A | Z15: 80 | AA15: 1 | AB15: 1
A16: 21197 | B16: CARREFOUR - SAI/SO AREA 6580, S/N - PARK SHOPPING - MGCO18545 | C16: SAI/SO AREA 6580 | D16: S/N | E16: SEM COMPLEMENTO | F16: GUARA | G16: Brasília | H16: DF | I16: 71219900 | J16: -15.8335067 , -47.9552839 | K16: MG CO 1 | L16: MG CO | M16: MGCO18545 | N16: Sim | O16: 45543915000343 | P16: BSB | Q16: VAREJO | S16: Park Shopping | T16: CARREFOUR | U16: VAREJO | V16: CARREFOUR | W16: CARREFOUR | X16: 70 | Y16: A | Z16: 80 | AA16: 1 | AB16: 1
A17: 21525 | B17: CASAS BAHIA - PRACA FLORIANO PEIXOTO, 38 - ZONA COMERCIAL - SPC11232 | C17: PRACA MARECHAL FLORIANO PEIXOTO | D17: 38 | E17: A,44 E 50 | F17: SANTO AMARO | G17: São Paulo | H17: SP | I17: 4751030 | J17: -23.652002 , -46.707207 | K17: SPC 8 | L17: SPC | M17: SPC11232 | N17: Sim | O17: 33041260100541 | P17: 1060 | Q17: VAREJO | S17: Loja De Rua | T17: CASAS BAHIA | U17: VAREJO | V17: VIA VAREJO | W17: CASAS BAHIA | X17: 70 | Y17: A | Z17: 80 | AA17: 0 | AB17: 0
A18: 21453 | B18: CASAS BAHIA - AVENIDA RIO VERDE, S/N - SHOPPING BURITI - MGCO20073 | C18: AVENIDA RIO VERDE | D18: S/N | E18: LOJAS141 E 143 | F18: VILA SAO TOMAZ | G18: Aparecida de Goiânia | H18: GO | I18: 74916260 | J18: -16.741322 , -49.277218 | K18: MG CO 2 | L18: MG CO | M18: MGCO20073 | N18: Sim | O18: 33041260108364 | P18: 1330 | Q18: VAREJO | S18: Shopping Buriti | T18: CASAS BAHIA | U18: VAREJO | V18: VIA VAREJO | W18: CASAS BAHIA | X18: 70 | Y18: A | Z18: 80 | AA18: 1 | AB18: 1
A19: 21477 | B19: CASAS BAHIA - AVENIDA TANCREDO NEVES, 3133 - SHOPPING SALVADOR - NE7415 | C19: AVENIDA TANCREDO NEVES | D19: 3133 | E19: SALAO COMERCIAL | F19: CAMINHO DAS ARVORES | G19: Salvador | H19: BA | I19: 41828920 | J19: -12.978583 , -38.454796 | K19: NE 4 | L19: NE | M19: NE7415 | N19: Sim | O19: 33041260139162 | P19: 1572 | Q19: VAREJO | S19: Shopping Salvador | T19: CASAS BAHIA | U19: VAREJO | V19: VIA VAREJO | W19: CASAS BAHIA | X19: 70 | Y19: A | Z19: 80 | AA19: 1 | AB19: 1
A20: 21700 | B20: CASAS BAHIA - RUA PADRE CARAPUCEIRO, 777 - SHOPPING RECIFE - NE39626 | C20: RUA CARAPUCEIRO | D20: 777 | E20: LUCS139/140 | F20: BOA VIAGEM | G20: Recife | H20: PE | I20: 51020900 | J20: -8.119827 , -34.905079 | K20: NE 1 | L20: NE | M20: NE39626 | N20: Sim | O20: 33041260186322 | P20: 2239 | Q20: VAREJO | S20: Shopping Recife | T20: CASAS BAHIA | U20: VAREJO | V20: VIA VAREJO | W20: CASAS BAHIA | X20: 70 | Y20: A | Z20: 80 | AA20: 1 | AB20: 1
A21: 22944 | B21: LOJAS AMERICANAS - AVENIDA DAS AMERICAS, 4666 - BARRA SHOPPING - RJES7550 | C21: AVENIDA DAS AMERICAS | D21: 4666 | E21: LOJA C,1,2 E 3 | F21: BARRA DA TIJUCA | G21: Rio de Janeiro | H21: RJ | I21: 22631004 | J21: -22.99758 , -43.358112 | K21: RJ ES 3 | L21: RJ ES | M21: RJES7550 | N21: Sim | O21: 776574088908 | P21: L067 | Q21: VAREJO | S21: Barra Shopping | T21: LOJAS AMERICANAS | U21: VAREJO | V21: LOJAS AMERICANAS | W21: LOJAS AMERICANAS | X21: 70 | Y21: A | Z21: 80 | AA21: 1 | AB21: 1
... A26: 85199 | B26: MAGAZINE LUIZA - AVENIDA RIO VERDE, S/N - SHOPPING BURITI - MGCO239760 | C26: AVENIDA RIO VERDE | D26: S/N | E26: Qd 102/104 LOJA 178 | F26: VILA SÃO TOMAZ | G26: Aparecida de Goiânia | H26: GO | I26: 74916260 | J26: -16.7410576, -49.2769892 | K26: MG CO 2 | L26: MG CO | M26: MGCO239760 | N26: Sim | O26: 47960950172763 | P26: 1563 | Q26: VAREJO | S26: Shopping Buriti | T26: MAGAZINE LUIZA | U26: VAREJO | V26: MAGAZINE LUIZA | W26: MAGAZINE LUIZA | X26: 70 | Y26: A | Z26: 80 | AA26: 1 | AB26: 1
A27: 106323 | B27: MAGAZINE LUIZA - AVENIDA DAS AMERICAS, 4666 - BARRA SHOPPING - RJES250470 | C27: AVENIDA DAS AMERICAS | D27: 4666 | F27: BARRA DA TIJUCA | G27: Rio De Janeiro | H27: RJ | I27: 22640102 | J27: -22.99758 , -43.358112 | K27: RJ ES 3 | L27: RJ ES | M27: RJES250470 | N27: Sim | O27: 47960950183706 | P27: 1644 | Q27: VAREJO | S27: Barra Shopping | T27: MAGAZINE LUIZA | U27: VAREJO | V27: MAGAZINE LUIZA | W27: MAGAZINE LUIZA | X27: 70 | Y27: A | Z27: 20 | AA27: 1 | AB27: 0
A28: 21179 | B28: CARREFOUR - RODOVIA REGIS BITTENCOURT KM 271, 2643 - SHOPPING TABOAO DA SERRA - SPC10654 | C28: RODOVIA REGIS BITTENCOURT | D28: 2643 | E28: KM 271,5 | F28: CIDADE INTERCAP | G28: Taboão da Serra | H28: SP | I28: 6768200 | J28: -23.615 , -46.776707 | K28: SPC 5 | L28: SPC | M28: SPC10654 | N28: Sim | O28: 45543915022401 | P28: STS | Q28: VAREJO | S28: Shopping Taboão Da Serra | T28: CARREFOUR | U28: VAREJO | V28: CARREFOUR | W28: CARREFOUR | X28: 69 | Y28: A | Z28: 80 | AA28: 0 | AB28: 0
A29: 23200 | B29: LOJAS AMERICANAS - RUA 15 DE NOVEMBRO, 8 - SHOPPING PLAZA NITEROI - RJES7540 | C29: RUA XV DE NOVEMBRO | D29: 8 | E29: LOJA 317 E 382 | F29: CENTRO | G29: Niterói | H29: RJ | I29: 24020120 | J29: -22.897249 , -43.123871 | K29: RJ ES 5 | L29: RJ ES | M29: RJES7540 | N29: Sim | O29: 776574080400 | P29: L087 | Q29: VAREJO | S29: Shopping Plaza Niteroi | T29: LOJAS AMERICANAS | U29: VAREJO | V29: LOJAS AMERICANAS | W29: LOJAS AMERICANAS | X29: 69 | Y29: A | Z29: 80 | AA29: 1 | AB29: 1
A30: 23742 | B30: MAGAZINE LUIZA - AVENIDA TANCREDO NEVES, 3133 - SHOPPING SALVADOR - NE41587 | C30: AVENIDA TANCREDO NEVES | D30: 3133 | E30: LUC 4019 | F30: CAMINHO DAS ARVORES | G30: Salvador | H30: BA | I30: 41828920 | J30: -12.978583 , -38.454796 | K30: NE 4 | L30: NE | M30: NE41587 | N30: Sim | O30: 47960950090953 | P30: 725 | Q30: VAREJO | S30: Shopping Salvador | T30: MAGAZINE LUIZA | U30: VAREJO | V30: MAGAZINE LUIZA | W30: MAGAZINE LUIZA | X30: 69 | Y30: A | Z30: 80 | AA30: 1 | AB30: 1
A31: 109188 | B31: MAGAZINE LUIZA - RUA JOSE DE ALVARENGA, 230 - RJES254860 | C31: RUA JOSE DE ALVARENGA | D31: 230 | F31: CENTRO | G31: Duque de Caxias | H31: RJ | I31: 25020140 | J31: -22.789356,-43.3135987 | K31: RJ ES 1 | L31: RJ ES | M31: RJES254860 | N31: Sim | O31: 47960950178290 | P31: 1619 | Q31: VAREJO | S31: Loja De Rua | T31: MAGAZINE LUIZA | U31: VAREJO | V31: MAGAZINE LUIZA | W31: MAGAZINE LUIZA | X31: 69 | Y31: A | Z31: 80 | AA31: 0 | AB31: 0
A32: 25475 | B32: VIVO - AVENIDA ROQUE PETRONI JUNIOR, 1089 - SHOPPING MORUMBI - SPC7261 | C32: AVENIDA ROQUE PETRONI JUNIOR | D32: 1089 | E32: LOJA 100 | F32: VILA GERTRUDES | G32: São Paulo | H32: SP | I32: 4707000 | J32: -23.623056 , -46.698708 | K32: SPC 8 | L32: SPC | M32: SPC7261 | N32: Sim | O32: 2558157006950 | P32: LOJA SHOPPING MORUMBI SP | Q32: VIVO | S32: Shopping Morumbi | T32: VIVO LP | U32: OPERADORA | V32: VIVO | W32: VIVO LP | X32: 69 | Y32: A | Z32: 20 | AA32: 1 | AB32: 0
A33: 21120 | B33: CARREFOUR - AVENIDA DEPUTADO JAMEL CECILIO, 3900 - ZONA COMERCIAL - MGCO6828 | C33: AVENIDA DEPUTADO JAMEL CECILIO | D33: 3900 | F33: JARDIM GOIÁS | G33: Goiânia | H33: GO | I33: 74810100 | J33: -16.711329 , -49.233458 | K33: MG CO 2 | L33: MG CO | M33: MGCO6828 | N33: Sim | O33: 45543915002478 | P33: GOS | Q33: VAREJO | S33: Loja De Rua | T33: CARREFOUR | U33: VAREJO | V33: CARREFOUR | W33: CARREFOUR | X33: 68 | Y33: A | Z33: 80 | AA33: 0 | AB33: 0
A34: 21133 | B34: CARREFOUR - AVENIDA INTERLAGOS, 2501 - SHOPPING INTERLAGOS - SPC20237 | C34: AVENIDA INTERLAGOS | D34: 2501 | F34: VILA CAMPO GRANDE | G34: São Paulo | H34: SP | I34: 4661200 | J34: -23.6773453954232 , -46.67554445341185 | K34: SPC 5 | L34: SPC | M34: SPC20237 | N34: Sim | O34: 45543915002125 | P34: SPI | Q34: VAREJO | S34: Shopping Interlagos | T34: CARREFOUR | U34: VAREJO | V34: CARREFOUR | W34: CARREFOUR | X34: 68 | Y34: A | Z34: 80 | AA34: 0 | AB34: 0
A35: 21148 | B35: CARREFOUR - AVENIDA PIRACEMA, 669 - SHOPPING TAMBORE - SPC6447 | C35: AVENIDA PIRACEMA | D35: 669 | F35: TAMBORE | G35: Barueri | H35: SP | I35: 6460030 | J35: -23.504423 , -46.834595 | K35: SPC 4 | L35: SPC | M35: SPC6447 | N35: Sim | O35: 45543915003288 | P35: TBE | Q35: VAREJO | S35: Shopping Tambore | T35: CARREFOUR | U35: VAREJO | V35: CARREFOUR | W35: CARREFOUR | X35: 68 | Y35: A | Z35: 80 | AA35: 0 | AB35: 0
A36: 21362 | B36: CASAS BAHIA - AVENIDA INTERLAGOS, 2255 - SHOPPING INTERLAGOS - SPC7613 | C36: AVENIDA INTERLAGOS | D36: 2255 | E36: LOJA ANCORA B | F36: VILA CAMPO GRANDE | G36: São Paulo | H36: SP | I36: 4661200 | J36: -23.676455 , -46.676823 | K36: SPC 5 | L36: SPC | M36: SPC7613 | N36: Sim | O36: 33041260100207 | P36: 1042 | Q36: VAREJO | S36: Shopping Interlagos | T36: CASAS BAHIA | U36: VAREJO | V36: VIA VAREJO | W36: CASAS BAHIA | X36: 68 | Y36: A | Z36: 80 | AA36: 0 | AB36: 0
A37: 21285 | B37: CASAS BAHIA - AVENIDA ARNIQUEIRA QS 1 RUA 210 LOTE 40, S/N - SHOPPING TAGUATINGA - MGCO5703 | C37: RUA DUZENTOS E DEZ, QS 1, LOTE 40 | D37: S/N | E37: LOTE 40 SUC 3068 | F37: TAGUATINGA | G37: Brasília | H37: DF | I37: 71950770 | J37: -15.84151 , -48.044277 | K37: MG CO 1 | L37: MG CO | M37: MGCO5703 | N37: Sim | O37: 33041260111314 | P37: 1610 | Q37: VAREJO | S37: Shopping Taguatinga | T37: CASAS BAHIA | U37: VAREJO | V37: VIA VAREJO | W37: CASAS BAHIA | X37: 68 | Y37: A | Z37: 80 | AA37: 1 | AB37: 1
A38: 23086 | B38: LOJAS AMERICANAS - AVENIDA REPLUBICA DO LIBANO, 251 - SHOPPING RIO MAR - NE5967 | C38: AVENIDA REPUBLICA DO LIBANO | D38: 251 | E38: LOJA 1089 | F38: PINA | G38: Recife | H38: PE | I38: 51110900 | J38: -8.086065 , -34.895043 | K38: NE 1 | L38: NE | M38: NE5967 | N38: Sim | O38: 776574129515 | P38: L141 | Q38: VAREJO | S38: Shopping Rio Mar | T38: LOJAS AMERICANAS | U38: VAREJO | V38: LOJAS AMERICANAS | W38: LOJAS AMERICANAS | X38: 68 | Y38: A | Z38: 20 | AA38: 1 | AB38: 0
A39: 23315 | B39: LOJAS AMERICANAS - RUA PADRE CARAPUCEIRO, 777 - SHOPPING RECIFE - NE5912 | C39: RUA CARAPUCEIRO | D39: 777 | E39: PE 117 E 118 | F39: BOA VIAGEM | G39: Recife | H39: PE | I39: 51020900 | J39: -8.119827 , -34.905079 | K39: NE 1 | L39: NE | M39: NE5912 | N39: Sim | O39: 776574164345 | P39: L088 | Q39: VAREJO | S39: Shopping Recife | T39: LOJAS AMERICANAS | U39: VAREJO | V39: LOJAS AMERICANAS | W39: LOJAS AMERICANAS | X39: 68 | Y39: A | Z39: 80 | AA39: 1 | AB39: 1
A40: 23578 | B40: MAGAZINE LUIZA - AVENIDA ARICANDUVA, 5555 - SHOPPING ARICANDUVA - SPC6374 | C40: AVENIDA ARICANDUVA | D40: 5555 | E40: ANCORA 3 | F40: VILA MATILDE | G40: São Paulo | H40: SP | I40: 3527900 | J40: -23.565256 , -46.503628 | K40: SPC 7 | L40: SPC | M40: SPC6374 | N40: Sim | O40: 47960950052784 | P40: 537 | Q40: VAREJO | S40: Shopping Aricanduva | T40: MAGAZINE LUIZA | U40: VAREJO | V40: MAGAZINE LUIZA | W40: MAGAZINE LUIZA | X40: 68 | Y40: A | Z40: 80 | AA40: 0 | AB40: 0
A41: 23664 | B41: MAGAZINE LUIZA - AVENIDA JOSE PINHEIRO BORGES, S/N - SHOPPING METRO ITAQUERA - SPC6498 | C41: AVENIDA JOSE PINHEIRO BORGES | D41: S/N | E41: LOJA 211 E 212 | F41: ITAQUERA | G41: São Paulo | H41: SP | I41: 8220385 | J41: -23.540546 , -46.470375 | K41: SPC 7 | L41: SPC | M41: SPC6498 | N41: Sim | O41: 47960950054990 | P41: 564 | Q41: VAREJO | S41: Shopping Itaquera | T41: MAGAZINE LUIZA | U41: VAREJO | V41: MAGAZINE LUIZA | W41: MAGAZINE LUIZA | X41: 68 | Y41: A | Z41: 80 | AA41: 0 | AB41: 0
A42: 23660 | B42: MAGAZINE LUIZA - AVENIDA JOAO WALLIG, 1800 - SHOPPING IGUATEMI PORTO ALEGRE - SUL7562 | C42: AVENIDA JOAO WALLIG | D42: 1800 | E42: LOJA 139 | F42: PASSO D'AREIA | G42: Porto Alegre | H42: RS | I42: 91349900 | J42: -30.024227 , -51.161819 | K42: SUL 2 | L42: SUL | M42: SUL7562 | N42: Sim | O42: 47960950032406 | P42: 413 | Q42: VAREJO | S42: Shopping Iguatemi Porto Alegre | T42: MAGAZINE LUIZA | U42: VAREJO | V42: MAGAZINE LUIZA | W42: MAGAZINE LUIZA | X42: 68 | Y42: A | Z42: 80 | AA42: 1 | AB42: 1
A43: 20768 | B43: BEMOL - AVENIDA MARIO YPIRANGA, 1300 - SHOPPING MANAUARA - N10233 | C43: AVENIDA MARIO YPIRANGA | D43: 1300 | E43: LOJA ANCORA 5 / 6 | F43: ADRIANOPOLIS | G43: Manaus | H43: AM | I43: 69057002 | J43: -3.104119 , -60.011795 | K43: N 1 | L43: N | M43: N10233 | N43: Sim | O43: 04565289002948 | P43: Manauara | Q43: VAREJO | S43: Shopping Manauara | T43: BEMOL | U43: VAREJO | V43: BEMOL | W43: BEMOL | X43: 67 | Y43: A | Z43: 80 | AA43: 1 | AB43: 1
A44: 21348 | B44: CASAS BAHIA - AVENIDA GOVERNADOR AMARAL PEIXOTO, 25 - ZONA COMERCIAL - RJES6993 | C44: AVENIDA GOVERNADOR AMARAL PEIXOTO | D44: 25 | E44: 1784,LOJAS 4,6 E 8 | F44: CENTRO | G44: Nova Iguaçu | H44: RJ | I44: 26210000 | J44: -22.760298505102785 , -43.448208426322026 | K44: RJ ES 1 | L44: RJ ES | M44: RJES6993 | N44: Sim | O44: 33041260082039 | P44: 1279 | Q44: VAREJO | S44: Loja De Rua | T44: CASAS BAHIA | U44: VAREJO | V44: VIA VAREJO | W44: CASAS BAHIA | X44: 67 | Y44: A | Z44: 80 | AA44: 0 | AB44: 0
...
